<?xml version="1.0" ?>
<!-- =================================================================================== -->
<!-- |    This document was autogenerated by xacro from new_robot.urdf                 | -->
<!-- |    EDITING THIS FILE BY HAND IS NOT RECOMMENDED                                 | -->
<!-- =================================================================================== -->
<robot name="my_robot1">
  <xacro:include filename="$(find my_robot)/urdf/my_robot.gazebo"/>
  <joint name="my_robot1__left_wheel_hinge" type="revolute">
    <parent link="my_robot1__robot_footprint"/>
    <child link="my_robot1__left_wheel"/>
    <origin rpy="0  0  0" xyz="0       0.16245  0"/>
    <axis xyz="0  1  0"/>
    <limit effort="-1.0" lower="-1e+16" upper="1e+16" velocity="-1.0"/>
  </joint>
  <joint name="my_robot1__right_wheel_hinge" type="revolute">
    <parent link="my_robot1__robot_footprint"/>
    <child link="my_robot1__right_wheel"/>
    <origin rpy="0  0  0" xyz="0      -0.16671  0"/>
    <axis xyz="0  1  0"/>
    <limit effort="-1.0" lower="-1e+16" upper="1e+16" velocity="-1.0"/>
  </joint>
  <joint name="my_robot1__robot_footprint_JOINT_1" type="revolute">
    <parent link="my_robot1__robot_footprint"/>
    <child link="my_robot1__right_wheel_clone_0"/>
    <origin rpy="0.00000000e+00  -6.10000000e-04  -5.00000000e-05" xyz="2.71230000e-01  -1.58130000e-01   1.60000000e-04"/>
    <axis xyz="1.00000000e+00   5.00000000e-05  -6.10000000e-04"/>
    <limit effort="-1.0" lower="-1.79769e+308" upper="1.79769e+308" velocity="-1.0"/>
  </joint>
  <joint name="my_robot1__robot_footprint_JOINT_3" type="revolute">
    <parent link="my_robot1__robot_footprint"/>
    <child link="my_robot1__left_wheel_clone"/>
    <origin rpy="0.00000000e+00  -6.10000000e-04  -5.00000000e-05" xyz="2.71250000e-01   1.65540000e-01   1.60000000e-04"/>
    <axis xyz="-5.00000000e-05   1.00000000e+00   0.00000000e+00"/>
    <limit effort="-1.0" lower="-1.79769e+308" upper="1.79769e+308" velocity="-1.0"/>
  </joint>
  <link name="my_robot1__robot_footprint">
    <inertial>
      <mass value="22.6037"/>
      <origin rpy="0  0  0" xyz="6.00000000e-05   0.00000000e+00   0.00000000e+00"/>
      <inertia ixx="0" ixy="0" ixz="-1.48675e-07" iyy="0" iyz="0" izz="0"/>
    </inertial>
    <collision name="my_robot1__robot_footprint_fixed_joint_lump__chassis_collision_collision">
      <origin rpy="0  0  0" xyz="0.14614  0.0037   0"/>
      <geometry>
        <box size="0.4 0.273634 0.1"/>
      </geometry>
    </collision>
    <collision name="my_robot1__robot_footprint_fixed_joint_lump__front_caster_collision_collision_2">
      <origin rpy="0  0  0" xyz="0.29614  0.0037  -0.05"/>
      <geometry>
        <sphere radius="0.068752"/>
      </geometry>
    </collision>
    <collision name="my_robot1__robot_footprint_fixed_joint_lump__back_caster_collision_collision_1">
      <origin rpy="0  0  0" xyz="-0.00385  0.0037  -0.05"/>
      <geometry>
        <sphere radius="0.068752"/>
      </geometry>
    </collision>
    <collision name="my_robot1__robot_footprint_fixed_joint_lump__hokuyo_collision_collision_4">
      <origin rpy="0  0  0" xyz="0.29614  0.0037   0.09999"/>
      <geometry>
        <box size="0.1 0.137779 0.1"/>
      </geometry>
    </collision>
    <collision name="my_robot1__robot_footprint_fixed_joint_lump__camera_collision_collision_3">
      <origin rpy="0  0  0" xyz="0.34614  0.0037   0"/>
      <geometry>
        <box size="0.05 0.068889 0.05"/>
      </geometry>
    </collision>
    <visual name="my_robot1__robot_footprint_fixed_joint_lump__chassis_visual_visual">
      <origin rpy="0  0  0" xyz="0.14614  0.0037   0"/>
      <geometry>
        <box size="0.4 0.273634 0.1"/>
      </geometry>
    </visual>
    <visual name="my_robot1__robot_footprint_fixed_joint_lump__back_caster_visual_visual_1">
      <origin rpy="0  0  0" xyz="-0.00385  0.0037  -0.05"/>
      <geometry>
        <sphere radius="0.0688894"/>
      </geometry>
    </visual>
    <visual name="my_robot1__robot_footprint_fixed_joint_lump__front_caster_visual_visual_2">
      <origin rpy="0  0  0" xyz="0.29614  0.0037  -0.05"/>
      <geometry>
        <sphere radius="0.0688894"/>
      </geometry>
    </visual>
    <visual name="my_robot1__robot_footprint_fixed_joint_lump__camera_visual_visual_3">
      <origin rpy="0  0  0" xyz="0.34614  0.0037   0"/>
      <geometry>
        <box size="0.05 0.068889 0.05"/>
      </geometry>
    </visual>
    <visual name="my_robot1__robot_footprint_fixed_joint_lump__hokuyo_visual_visual_4">
      <origin rpy="0  0  0" xyz="0.29614  0.0037   0.09999"/>
      <geometry>
        <mesh filename="package://my_robot/meshes/hokuyo.dae"/>
      </geometry>
    </visual>
  </link>
  <link name="my_robot1__left_wheel">
    <inertial>
      <mass value="5"/>
      <origin rpy="0      1.5707  1.5707" xyz="0  0  0"/>
      <inertia ixx="0.1" ixy="0" ixz="0" iyy="0.1" iyz="0" izz="0.1"/>
    </inertial>
    <collision name="my_robot1__left_wheel_collision_collision">
      <origin rpy="3.14159  1.57079 -1.57089" xyz="0  0  0"/>
      <geometry>
        <cylinder length="0.05" radius="0.1"/>
      </geometry>
    </collision>
    <visual name="my_robot1__left_wheel_visual_visual">
      <origin rpy="-3.13202  1.57079 -1.56132" xyz="0  0  0"/>
      <geometry>
        <cylinder length="0.05" radius="0.1"/>
      </geometry>
    </visual>
  </link>
  <link name="my_robot1__left_wheel_clone">
    <inertial>
      <mass value="5"/>
      <origin rpy="0      1.5707  1.5707" xyz="0  0  0"/>
      <inertia ixx="0.1" ixy="0" ixz="0" iyy="0.1" iyz="0" izz="0.1"/>
    </inertial>
    <collision name="my_robot1__left_wheel_collision_collision">
      <origin rpy="-3.13202  1.57079 -1.56132" xyz="0  0  0"/>
      <geometry>
        <cylinder length="0.05" radius="0.1"/>
      </geometry>
    </collision>
    <visual name="my_robot1__left_wheel_visual_visual">
      <origin rpy="-3.12268  1.57079 -1.55198" xyz="0  0  0"/>
      <geometry>
        <cylinder length="0.05" radius="0.1"/>
      </geometry>
    </visual>
  </link>
  <link name="my_robot1__right_wheel">
    <inertial>
      <mass value="5"/>
      <origin rpy="0      1.5707  1.5707" xyz="0  0  0"/>
      <inertia ixx="0.1" ixy="0" ixz="0" iyy="0.1" iyz="0" izz="0.1"/>
    </inertial>
    <collision name="my_robot1__right_wheel_collision_collision">
      <origin rpy="3.14159  1.57079 -1.57089" xyz="0  0  0"/>
      <geometry>
        <cylinder length="0.05" radius="0.1"/>
      </geometry>
    </collision>
    <visual name="my_robot1__right_wheel_visual_visual">
      <origin rpy="-3.12268  1.57079 -1.55198" xyz="0  0  0"/>
      <geometry>
        <cylinder length="0.05" radius="0.1"/>
      </geometry>
    </visual>
  </link>
  <link name="my_robot1__right_wheel_clone_0">
    <inertial>
      <mass value="5"/>
      <origin rpy="0      1.5707  1.5707" xyz="0  0  0"/>
      <inertia ixx="0.1" ixy="0" ixz="0" iyy="0.1" iyz="0" izz="0.1"/>
    </inertial>
    <collision name="my_robot1__right_wheel_collision_collision">
      <origin rpy="-3.13202  1.57079 -1.56132" xyz="0  0  0"/>
      <geometry>
        <cylinder length="0.05" radius="0.1"/>
      </geometry>
    </collision>
    <visual name="my_robot1__right_wheel_visual_visual">
      <origin rpy="-3.12268  1.57079 -1.55198" xyz="0  0  0"/>
      <geometry>
        <cylinder length="0.05" radius="0.1"/>
      </geometry>
    </visual>
  </link>
</robot>

